<?xml version='1.0' encoding='utf-8'?>
<robot name="R1RightSimplified">
  <link name="torso_link4">
    <inertial>
      <origin xyz="-0.0025153 3.1179E-07 0.35873" rpy="0 0 0" />
      <mass value="16.778" />
      <inertia ixx="0.015187" ixy="7.199E-08" ixz="0.00054617" iyy="0.013478" iyz="-2.0225E-07" izz="0.017316" />
    </inertial>
    <visual>
      <origin xyz="0 0 0" rpy="0 0 0" />
      <geometry>
        <mesh filename="meshes/torso_link4.STL" />
      </geometry>
      <material name="">
        <color rgba="0.79216 0.81961 0.93333 1" />
      </material>
    </visual>
  </link>
  <link name="zed_link">
    <inertial>
      <origin xyz="-0.070413 -2.7792E-07 -0.015905" rpy="0 0 0" />
      <mass value="3.3094" />
      <inertia ixx="0.012229" ixy="-1.333E-08" ixz="-0.00028961" iyy="0.010375" iyz="1.8965E-07" izz="0.014618" />
    </inertial>
    <visual>
      <origin xyz="0 0 0" rpy="0 0 0" />
      <geometry>
        <mesh filename="meshes/zed_link.STL" />
      </geometry>
      <material name="">
        <color rgba="0.81176 0.84314 0.9098 1" />
      </material>
    </visual>
  </link>
  <joint name="zed_axis" type="fixed">
    <origin xyz="0.06739 0 0.4753" rpy="0 0.34906 0" />
    <parent link="torso_link4" />
    <child link="zed_link" />
    <axis xyz="0 0 0" />
  </joint>
  <link name="right_arm_link1">
    <inertial>
      <origin xyz="0.0020139 0.0089421 0.19171" rpy="0 0 0" />
      <mass value="1.319" />
      <inertia ixx="0.00058101" ixy="-7.5672E-09" ixz="-2.9207E-08" iyy="0.00070857" iyz="8.5639E-07" izz="0.00044583" />
    </inertial>
    <visual>
      <origin xyz="0 0 0" rpy="0 0 0" />
      <geometry>
        <mesh filename="meshes/right_arm_link1.STL" />
      </geometry>
      <material name="">
        <color rgba="0.79216 0.81961 0.93333 1" />
      </material>
    </visual>
    <collision>
      <origin xyz="0 0 0" rpy="0 0 0" />
      <geometry>
        <mesh filename="meshes_convex/right_arm_link1.obj" />
      </geometry>
    </collision>
  </link>
  <joint name="right_arm_joint1" type="revolute">
    <origin xyz="-0.0003367 -0.13609 0.27773" rpy="1.5786 -0.00054698 0" />
    <parent link="torso_link4" />
    <child link="right_arm_link1" />
    <axis xyz="0 0 1" />
    <limit lower="-2.8798" upper="2.8798" effort="40" velocity="20.944" />
  </joint>
  <link name="right_arm_link2">
    <inertial>
      <origin xyz="-0.23622 -0.016354 0.00013181" rpy="0 0 0" />
      <mass value="1.3" />
      <inertia ixx="0.00060639" ixy="-0.00041823" ixz="-0.00014959" iyy="0.0075936" iyz="-8.0946E-06" izz="0.0075712" />
    </inertial>
    <visual>
      <origin xyz="0 0 0" rpy="0 0 0" />
      <geometry>
        <mesh filename="meshes/right_arm_link2.STL" />
      </geometry>
      <material name="">
        <color rgba="0.79216 0.81961 0.93333 1" />
      </material>
    </visual>
    <collision>
      <origin xyz="0 0 0" rpy="0 0 0" />
      <geometry>
        <mesh filename="meshes_convex/right_arm_link2.obj" />
      </geometry>
    </collision>
  </link>
  <joint name="right_arm_joint2" type="revolute">
    <origin xyz="0 0.00087053 0.11185" rpy="-1.5786 0 -0.00054696" />
    <parent link="right_arm_link1" />
    <child link="right_arm_link2" />
    <axis xyz="0 0 1" />
    <limit lower="0" upper="3.2289" effort="40" velocity="20.944" />
  </joint>
  <link name="right_arm_link3">
    <inertial>
      <origin xyz="0.045115 -0.054616 0.00045605" rpy="0 0 0" />
      <mass value="0.818" />
      <inertia ixx="0.00060107" ixy="0.00022466" ixz="7.1151E-06" iyy="0.0013959" iyz="-9.7494E-06" izz="0.0015027" />
    </inertial>
    <visual>
      <origin xyz="0 0 0" rpy="0 0 0" />
      <geometry>
        <mesh filename="meshes/right_arm_link3.STL" />
      </geometry>
      <material name="">
        <color rgba="0.79216 0.81961 0.93333 1" />
      </material>
    </visual>
    <collision>
      <origin xyz="0 0 0" rpy="0 0 0" />
      <geometry>
        <mesh filename="meshes_convex/right_arm_link3.obj" />
      </geometry>
    </collision>
  </link>
  <joint name="right_arm_joint3" type="revolute">
    <origin xyz="-0.34928 -0.020001 0" rpy="0 0 0" />
    <parent link="right_arm_link2" />
    <child link="right_arm_link3" />
    <axis xyz="0 0 1" />
    <limit lower="-3.3161" upper="0" effort="27" velocity="7.5398" />
  </joint>
  <link name="right_arm_link4">
    <inertial>
      <origin xyz="-8.1603E-07 0.0023773 0.24285" rpy="0 0 0" />
      <mass value="0.816" />
      <inertia ixx="9.7044E-05" ixy="-5.3698E-09" ixz="2.2378E-09" iyy="0.00010174" iyz="-8.2619E-07" izz="8.45E-05" />
    </inertial>
    <visual>
      <origin xyz="0 0 0" rpy="0 0 0" />
      <geometry>
        <mesh filename="meshes/right_arm_link4.STL" />
      </geometry>
      <material name="">
        <color rgba="1 1 1 1" />
      </material>
    </visual>
    <collision>
      <origin xyz="0 0 0" rpy="0 0 0" />
      <geometry>
        <mesh filename="meshes_convex/right_arm_link4.obj" />
      </geometry>
    </collision>
  </link>
  <joint name="right_arm_joint4" type="revolute">
    <origin xyz="0.02735 -0.069767 0" rpy="0 -1.5708 3.1416" />
    <parent link="right_arm_link3" />
    <child link="right_arm_link4" />
    <axis xyz="0 0 1" />
    <limit lower="-2.8798" upper="2.8798" effort="7" velocity="25.133" />
  </joint>
  <link name="right_arm_link5">
    <inertial>
      <origin xyz="0.054309 -2.4377E-05 0.0011809" rpy="0 0 0" />
      <mass value="0.801" />
      <inertia ixx="8.4E-05" ixy="6.8153E-08" ixz="1.6234E-05" iyy="0.00011332" iyz="-1.104E-07" izz="9.8499E-05" />
    </inertial>
    <visual>
      <origin xyz="0 0 0" rpy="0 0 0" />
      <geometry>
        <mesh filename="meshes/right_arm_link5.STL" />
      </geometry>
      <material name="">
        <color rgba="1 1 1 1" />
      </material>
    </visual>
    <collision>
      <origin xyz="0 0 0" rpy="0 0 0" />
      <geometry>
        <mesh filename="meshes_convex/right_arm_link5.obj" />
      </geometry>
    </collision>
  </link>
  <joint name="right_arm_joint5" type="revolute">
    <origin xyz="0 0.0025 0.2463" rpy="-1.5708 -1.5703 0.0077846" />
    <parent link="right_arm_link4" />
    <child link="right_arm_link5" />
    <axis xyz="0 0 1" />
    <limit lower="-1.6581" upper="1.6581" effort="7" velocity="25.133" />
  </joint>
  <link name="right_arm_link6">
    <inertial>
      <origin xyz="-2.223E-08 -5.7207E-08 -0.031107" rpy="0 0 0" />
      <mass value="0.465" />
      <inertia ixx="0.00016512" ixy="-4.3557E-07" ixz="-5.7705E-10" iyy="9.864E-05" iyz="7.4373E-11" izz="0.00017588" />
    </inertial>
    <visual>
      <origin xyz="0 0 0" rpy="0 0 0" />
      <geometry>
        <mesh filename="meshes/right_arm_link6.STL" />
      </geometry>
      <material name="">
        <color rgba="0.82353 0.82353 1 1" />
      </material>
    </visual>
    <collision>
      <origin xyz="0 0 0" rpy="0 0 0" />
      <geometry>
        <mesh filename="meshes_vhacd/right_arm_link6_vhacd.obj" />
      </geometry>
    </collision>
  </link>
  <joint name="right_arm_joint6" type="revolute">
    <origin xyz="0.16215 -0.00010784 -0.0024999" rpy="1.5708 0 1.5703" />
    <parent link="right_arm_link5" />
    <child link="right_arm_link6" />
    <axis xyz="0 0 1" />
    <limit lower="-2.8798" upper="2.8798" effort="7" velocity="25.133" />
  </joint>
  <link name="right_gripper_link1">
    <inertial>
      <origin xyz="-0.019593 -0.0055293 -0.015071" rpy="0 0 0" />
      <mass value="0.057" />
      <inertia ixx="2.4056E-06" ixy="-4.5884E-08" ixz="3.9934E-07" iyy="6.4839E-06" iyz="-6.8181E-08" izz="5.7118E-06" />
    </inertial>
    <visual>
      <origin xyz="0 0 0" rpy="0 0 0" />
      <geometry>
        <mesh filename="meshes/right_gripper_link1.STL" />
      </geometry>
      <material name="">
        <color rgba="0.82353 0.82353 1 1" />
      </material>
    </visual>
    <collision>
      <origin xyz="0 0 0" rpy="0 0 0" />
      <geometry>
        <mesh filename="meshes_convex/right_gripper_link1.obj" />
      </geometry>
    </collision>
  </link>
  <joint name="right_gripper_axis1" type="prismatic">
    <origin xyz="-1.5963E-05 0.013454 0.03689" rpy="-1.5745 -1.5703 0.0037081" />
    <parent link="right_arm_link6" />
    <child link="right_gripper_link1" />
    <axis xyz="0 0 1" />
    <limit lower="0" upper="0.05" effort="100" velocity="0.25" />
  </joint>
  <link name="right_gripper_link2">
    <inertial>
      <origin xyz="-0.019586 -0.0055507 -0.015071" rpy="0 0 0" />
      <mass value="0.057" />
      <inertia ixx="2.4057E-06" ixy="-5.033E-08" ixz="3.9941E-07" iyy="6.4838E-06" iyz="-6.7746E-08" izz="5.7118E-06" />
    </inertial>
    <visual>
      <origin xyz="0 0 0" rpy="0 0 0" />
      <geometry>
        <mesh filename="meshes/right_gripper_link2.STL" />
      </geometry>
      <material name="">
        <color rgba="0.82353 0.82353 1 1" />
      </material>
    </visual>
    <collision>
      <origin xyz="0 0 0" rpy="0 0 0" />
      <geometry>
        <mesh filename="meshes_convex/right_gripper_link2.obj" />
      </geometry>
    </collision>
  </link>
  <joint name="right_gripper_axis2" type="prismatic">
    <origin xyz="1.5816E-05 -0.013454 0.03689" rpy="1.5671 -1.5703 0.0037081" />
    <parent link="right_arm_link6" />
    <child link="right_gripper_link2" />
    <axis xyz="0 0 1" />
    <limit lower="0" upper="0.05" effort="100" velocity="0.25" />
  </joint>
</robot>